2022-10-15 21:53:34,092 ERROR: Exception on /edit_profile [POST] [in E:\REDxEd\Programacao\Flask-Mega-Tutorial\microblog\venv\lib\site-packages\flask\app.py:1741]
Traceback (most recent call last):
  File "E:\REDxEd\Programacao\Flask-Mega-Tutorial\microblog\venv\lib\site-packages\sqlalchemy\engine\base.py", line 1900, in _execute_context
    self.dialect.do_execute(
  File "E:\REDxEd\Programacao\Flask-Mega-Tutorial\microblog\venv\lib\site-packages\sqlalchemy\engine\default.py", line 736, in do_execute
    cursor.execute(statement, parameters)
sqlite3.OperationalError: database is locked

The above exception was the direct cause of the following exception:

Traceback (most recent call last):
  File "E:\REDxEd\Programacao\Flask-Mega-Tutorial\microblog\venv\lib\site-packages\flask\app.py", line 2525, in wsgi_app
    response = self.full_dispatch_request()
  File "E:\REDxEd\Programacao\Flask-Mega-Tutorial\microblog\venv\lib\site-packages\flask\app.py", line 1822, in full_dispatch_request
    rv = self.handle_user_exception(e)
  File "E:\REDxEd\Programacao\Flask-Mega-Tutorial\microblog\venv\lib\site-packages\flask\app.py", line 1820, in full_dispatch_request
    rv = self.dispatch_request()
  File "E:\REDxEd\Programacao\Flask-Mega-Tutorial\microblog\venv\lib\site-packages\flask\app.py", line 1796, in dispatch_request
    return self.ensure_sync(self.view_functions[rule.endpoint])(**view_args)
  File "E:\REDxEd\Programacao\Flask-Mega-Tutorial\microblog\venv\lib\site-packages\flask_login\utils.py", line 290, in decorated_view
    return current_app.ensure_sync(func)(*args, **kwargs)
  File "E:\REDxEd\Programacao\Flask-Mega-Tutorial\microblog\app\routes.py", line 82, in edit_profile
    db.session.commit()
  File "<string>", line 2, in commit
  File "E:\REDxEd\Programacao\Flask-Mega-Tutorial\microblog\venv\lib\site-packages\sqlalchemy\orm\session.py", line 1451, in commit
    self._transaction.commit(_to_root=self.future)
  File "E:\REDxEd\Programacao\Flask-Mega-Tutorial\microblog\venv\lib\site-packages\sqlalchemy\orm\session.py", line 829, in commit
    self._prepare_impl()
  File "E:\REDxEd\Programacao\Flask-Mega-Tutorial\microblog\venv\lib\site-packages\sqlalchemy\orm\session.py", line 808, in _prepare_impl
    self.session.flush()
  File "E:\REDxEd\Programacao\Flask-Mega-Tutorial\microblog\venv\lib\site-packages\sqlalchemy\orm\session.py", line 3386, in flush
    self._flush(objects)
  File "E:\REDxEd\Programacao\Flask-Mega-Tutorial\microblog\venv\lib\site-packages\sqlalchemy\orm\session.py", line 3526, in _flush
    transaction.rollback(_capture_exception=True)
  File "E:\REDxEd\Programacao\Flask-Mega-Tutorial\microblog\venv\lib\site-packages\sqlalchemy\util\langhelpers.py", line 70, in __exit__
    compat.raise_(
  File "E:\REDxEd\Programacao\Flask-Mega-Tutorial\microblog\venv\lib\site-packages\sqlalchemy\util\compat.py", line 208, in raise_
    raise exception
  File "E:\REDxEd\Programacao\Flask-Mega-Tutorial\microblog\venv\lib\site-packages\sqlalchemy\orm\session.py", line 3486, in _flush
    flush_context.execute()
  File "E:\REDxEd\Programacao\Flask-Mega-Tutorial\microblog\venv\lib\site-packages\sqlalchemy\orm\unitofwork.py", line 456, in execute
    rec.execute(self)
  File "E:\REDxEd\Programacao\Flask-Mega-Tutorial\microblog\venv\lib\site-packages\sqlalchemy\orm\unitofwork.py", line 630, in execute
    util.preloaded.orm_persistence.save_obj(
  File "E:\REDxEd\Programacao\Flask-Mega-Tutorial\microblog\venv\lib\site-packages\sqlalchemy\orm\persistence.py", line 237, in save_obj
    _emit_update_statements(
  File "E:\REDxEd\Programacao\Flask-Mega-Tutorial\microblog\venv\lib\site-packages\sqlalchemy\orm\persistence.py", line 1001, in _emit_update_statements
    c = connection._execute_20(
  File "E:\REDxEd\Programacao\Flask-Mega-Tutorial\microblog\venv\lib\site-packages\sqlalchemy\engine\base.py", line 1705, in _execute_20
    return meth(self, args_10style, kwargs_10style, execution_options)
  File "E:\REDxEd\Programacao\Flask-Mega-Tutorial\microblog\venv\lib\site-packages\sqlalchemy\sql\elements.py", line 333, in _execute_on_connection
    return connection._execute_clauseelement(
  File "E:\REDxEd\Programacao\Flask-Mega-Tutorial\microblog\venv\lib\site-packages\sqlalchemy\engine\base.py", line 1572, in _execute_clauseelement
    ret = self._execute_context(
  File "E:\REDxEd\Programacao\Flask-Mega-Tutorial\microblog\venv\lib\site-packages\sqlalchemy\engine\base.py", line 1943, in _execute_context
    self._handle_dbapi_exception(
  File "E:\REDxEd\Programacao\Flask-Mega-Tutorial\microblog\venv\lib\site-packages\sqlalchemy\engine\base.py", line 2124, in _handle_dbapi_exception
    util.raise_(
  File "E:\REDxEd\Programacao\Flask-Mega-Tutorial\microblog\venv\lib\site-packages\sqlalchemy\util\compat.py", line 208, in raise_
    raise exception
  File "E:\REDxEd\Programacao\Flask-Mega-Tutorial\microblog\venv\lib\site-packages\sqlalchemy\engine\base.py", line 1900, in _execute_context
    self.dialect.do_execute(
  File "E:\REDxEd\Programacao\Flask-Mega-Tutorial\microblog\venv\lib\site-packages\sqlalchemy\engine\default.py", line 736, in do_execute
    cursor.execute(statement, parameters)
sqlalchemy.exc.OperationalError: (sqlite3.OperationalError) database is locked
[SQL: UPDATE user SET username=? WHERE user.id = ?]
[parameters: ('Edson Gomes', 3)]
(Background on this error at: https://sqlalche.me/e/14/e3q8)
2022-10-15 21:59:25,980 INFO: Microblog startup [in E:\REDxEd\Programacao\Flask-Mega-Tutorial\microblog\app\__init__.py:49]
